C++의 예외 처리(Exception Handling)는 **프로그램 실행 중 발생할 수 있는 오류를 감지하고 적절히 처리하는 기법**입니다. 이를 통해 프로그램이 비정상적으로 종료되지 않고, 예외 상황을 우아하게 처리할 수 있습니다.

## **1. 예외 처리 기본 구조 (`try`, `throw`, `catch`)**

C++에서 예외 처리는 `try`, `throw`, `catch` 키워드를 사용합니다.

```
try {
    // 예외가 발생할 가능성이 있는 코드
    throw "예외 발생!";  // 예외 발생 (throw)
} 
catch (const char* msg) {
    // 예외 처리 (catch)
    std::cout << "예외 처리: " << msg << std::endl;
}
```
### **예외 처리 과정**

1. `try` 블록 안의 코드 실행 중 예외가 발생하면 `throw`가 호출됩니다.
2. `throw`가 예외를 던지면(`throw "예외 발생!"`), 실행이 즉시 중단되고 `catch` 블록에서 예외를 처리합니다.
3. 적절한 `catch` 블록이 있으면 예외가 처리되며, 프로그램이 계속 실행됩니다.

---

## **2. 다양한 예외 유형**

C++에서는 다양한 데이터 유형을 예외로 던질 수 있습니다.

### **(1) 정수 예외**

```
try {
    throw 42;  // 정수 예외 발생
} 
catch (int e) {
    std::cout << "정수 예외 발생: " << e << std::endl;
}
```
### **(2) 문자열 예외**

```
try {
    throw std::string("파일을 찾을 수 없습니다.");  // 문자열 예외 발생
} 
catch (std::string e) {
    std::cout << "문자열 예외 발생: " << e << std::endl;
}
```

### **(3) 사용자 정의 예외 (클래스)**

사용자 정의 예외 클래스를 만들 수도 있습니다.

```
#include <iostream>
#include <exception>

// 사용자 정의 예외 클래스
class MyException : public std::exception {
public:
    const char* what() const noexcept override {
        return "사용자 정의 예외 발생!";
    }
};

int main() {
    try {
        throw MyException();  // 사용자 정의 예외 발생
    } 
    catch (const MyException& e) {
        std::cout << e.what() << std::endl;
    }
}
```
- `what()` 함수는 예외 메시지를 반환하는 표준 함수입니다.

---

## **3. 다중 `catch` 블록**

하나의 `try` 블록에서 여러 유형의 예외를 처리할 수 있습니다.

```
try {
    throw 3.14;  // double 타입 예외 발생
} 
catch (int e) {
    std::cout << "정수 예외 발생: " << e << std::endl;
} 
catch (double e) {
    std::cout << "실수 예외 발생: " << e << std::endl;
} 
catch (...) {
    std::cout << "알 수 없는 예외 발생" << std::endl;
}
```

- `catch (...)` 는 모든 예외를 처리하는 기본 블록입니다.

---

## **4. 예외 다시 던지기 (`rethrow`)**

예외를 한 번 처리한 후 다시 던질 수도 있습니다.

```
void func() {
    try {
        throw std::runtime_error("에러 발생!");
    } 
    catch (const std::runtime_error& e) {
        std::cout << "func()에서 처리: " << e.what() << std::endl;
        throw;  // 예외를 다시 던짐
    }
}

int main() {
    try {
        func();
    } 
    catch (const std::runtime_error& e) {
        std::cout << "main()에서 다시 처리: " << e.what() << std::endl;
    }
}

```

- `throw;` 문을 사용하면 동일한 예외를 다시 던질 수 있습니다.

---

## **5. 예외 처리와 동적 메모리 해제**

예외가 발생하면 **스택이 풀리면서 지역 객체들은 자동으로 소멸**됩니다. 하지만 `new`로 할당한 동적 메모리는 자동으로 해제되지 않으므로 주의해야 합니다.



- 예외가 발생하면 반드시 `delete`를 호출하여 **메모리 누수를 방지**해야 합니다.

---

## **6. 예외 처리와 `noexcept`**

C++11 이상에서는 `noexcept`를 사용하여 예외를 던지지 않는 함수임을 명시할 수 있습니다.

```
void func() {
    int* p = new int[10];  // 동적 할당
    try {
        throw std::runtime_error("메모리 누수 발생 가능!");
    } 
    catch (...) {
        delete[] p;  // 메모리 해제
        throw;  // 예외 다시 던지기
    }
}

int main() {
    try {
        func();
    } 
    catch (const std::exception& e) {
        std::cout << "예외 처리: " << e.what() << std::endl;
    }
}
```

- `noexcept`가 있는 함수에서 예외를 던지면 `std::terminate()`가 호출되어 프로그램이 강제 종료됩니다.

---

## **정리**

✅ `try` 블록에서 예외가 발생하면 `throw`로 던지고 `catch`에서 처리  
✅ 여러 유형의 예외를 다중 `catch`로 처리 가능  
✅ `throw;`를 이용해 예외를 다시 던질 수 있음  
✅ 동적 메모리를 할당했다면 `catch`에서 반드시 해제  
✅ `noexcept`로 예외가 발생하지 않음을 명시할 수 있음

C++ 예외 처리는 프로그램의 안정성을 높이는 데 필수적인 기법이므로, 메모리 관리와 함께 신중하게 사용해야 합니다. 🚀